Traceback (most recent call last):
  File "/home/mjirka/anaconda3/lib/python3.8/site-packages/jupyter_cache/executors/utils.py", line 51, in single_nb_execution
    executenb(
  File "/home/mjirka/anaconda3/lib/python3.8/site-packages/nbclient/client.py", line 1112, in execute
    return NotebookClient(nb=nb, resources=resources, km=km, **kwargs).execute()
  File "/home/mjirka/anaconda3/lib/python3.8/site-packages/nbclient/util.py", line 74, in wrapped
    return just_run(coro(*args, **kwargs))
  File "/home/mjirka/anaconda3/lib/python3.8/site-packages/nbclient/util.py", line 53, in just_run
    return loop.run_until_complete(coro)
  File "/home/mjirka/anaconda3/lib/python3.8/asyncio/base_events.py", line 616, in run_until_complete
    return future.result()
  File "/home/mjirka/anaconda3/lib/python3.8/site-packages/nbclient/client.py", line 553, in async_execute
    await self.async_execute_cell(
  File "/home/mjirka/anaconda3/lib/python3.8/site-packages/nbclient/client.py", line 857, in async_execute_cell
    self._check_raise_for_error(cell, exec_reply)
  File "/home/mjirka/anaconda3/lib/python3.8/site-packages/nbclient/client.py", line 760, in _check_raise_for_error
    raise CellExecutionError.from_cell_and_msg(cell, exec_reply_content)
nbclient.exceptions.CellExecutionError: An error occurred while executing the following cell:
------------------
#
# metoda puleni intervalu

# demonstrace metody puleni intervalu pro nelinearni rovnice

# nadefinujeme f(x) a budeme hledat reseni f(x)=0
def f(x):
    return np.sin(x)-0.5

iteraci = 50 # celkovy pocet iteraci

# pocatecni body omezujici reseni
a = 0 
b = 1

# budeme si prubezne ukladat odhad reseni a chybu odhadu
epsilon = np.zeros((iteraci)) # odhad chyby, tedy delku intervalu <a,b> v jednotlivych krocich
reseni = np.zeros((iteraci)) # aktualni odhad reseni

for i in range(iteraci):
    # DOPLNTE
    #
    # DOPLNTE


koren = reseni[-1] # odhad konecneho reseni
chyba = epsilon[-1] # odhad konecne chyby


fig, ax = plt.subplots(1,2,figsize=(15,5))

# zobrazime vyvoj reseni v zavislosti na iteracich
ax[0].plot(range(iteraci),reseni,label='reseni')
ax[0].set_ylabel('reseni')
ax[0].set_xlabel('iterace')
ax[0].legend()

# zobrazime vyvoj chyby v zavislosti na iteracich
ax[1].plot(range(iteraci),epsilon,label='vyvoj chyby')
ax[1].set_ylabel(r'$\epsilon$')
ax[1].set_xlabel('iterace')
ax[1].legend()

# overeni reseni
spravne_reseni = fsolve(f, a)
print('f(x)=0 pro x= ',spravne_reseni)
------------------

[0;36m  File [0;32m"<ipython-input-2-c9b3c6036b02>"[0;36m, line [0;32m26[0m
[0;31m    koren = reseni[-1] # odhad konecneho reseni[0m
[0m    ^[0m
[0;31mIndentationError[0m[0;31m:[0m expected an indented block

IndentationError: expected an indented block (<ipython-input-2-c9b3c6036b02>, line 26)

